<?xml version="1.0" encoding="UTF-8"?>
<testng-results ignored="0" total="7" passed="3" failed="4" skipped="0">
  <reporter-output>
  </reporter-output>
  <suite started-at="2023-02-24T11:17:10 IST" name="Suite" finished-at="2023-02-24T11:17:16 IST" duration-ms="5418">
    <groups>
    </groups>
    <test started-at="2023-02-24T11:17:10 IST" name="Create Customer API Test" finished-at="2023-02-24T11:17:15 IST" duration-ms="4181">
      <class name="com.home.APITestingFramework.testcases.CreateCustomerTest">
        <test-method signature="validateCreateCustomerAPIWithInValidSecretkey(java.util.Hashtable)[pri:0, instance:com.home.APITestingFramework.testcases.CreateCustomerTest@3d3f761a]" started-at="2023-02-24T11:17:10 IST" name="validateCreateCustomerAPIWithInValidSecretkey" data-provider="data" finished-at="2023-02-24T11:17:14 IST" duration-ms="3245" status="FAIL">
          <params>
            <param index="0">
              <value>
                <![CDATA[{email=smitacustone@gmail.com, name=Smita Patil, description=This is a test customer one for API Testing Framework}]]>
              </value>
            </param>
          </params>
          <exception class="java.lang.AssertionError">
            <message>
              <![CDATA[expected [200] but found [401]]]>
            </message>
            <full-stacktrace>
              <![CDATA[java.lang.AssertionError: expected [200] but found [401]
at org.testng.Assert.fail(Assert.java:110)
at org.testng.Assert.failNotEquals(Assert.java:1413)
at org.testng.Assert.assertEqualsImpl(Assert.java:149)
at org.testng.Assert.assertEquals(Assert.java:131)
at org.testng.Assert.assertEquals(Assert.java:1240)
at org.testng.Assert.assertEquals(Assert.java:1274)
at com.home.APITestingFramework.testcases.CreateCustomerTest.validateCreateCustomerAPIWithInValidSecretkey(CreateCustomerTest.java:44)
at java.base/jdk.internal.reflect.NativeMethodAccessorImpl.invoke0(Native Method)
at java.base/jdk.internal.reflect.NativeMethodAccessorImpl.invoke(NativeMethodAccessorImpl.java:78)
at java.base/jdk.internal.reflect.DelegatingMethodAccessorImpl.invoke(DelegatingMethodAccessorImpl.java:43)
at java.base/java.lang.reflect.Method.invoke(Method.java:567)
at org.testng.internal.invokers.MethodInvocationHelper.invokeMethod(MethodInvocationHelper.java:139)
at org.testng.internal.invokers.TestInvoker.invokeMethod(TestInvoker.java:677)
at org.testng.internal.invokers.TestInvoker.invokeTestMethod(TestInvoker.java:221)
at org.testng.internal.invokers.TestMethodWithDataProviderMethodWorker.call(TestMethodWithDataProviderMethodWorker.java:80)
at org.testng.internal.invokers.TestMethodWithDataProviderMethodWorker.call(TestMethodWithDataProviderMethodWorker.java:17)
at java.base/java.util.concurrent.FutureTask.run(FutureTask.java:264)
at java.base/java.util.concurrent.Executors$RunnableAdapter.call(Executors.java:515)
at java.base/java.util.concurrent.FutureTask.run(FutureTask.java:264)
at java.base/java.util.concurrent.ThreadPoolExecutor.runWorker(ThreadPoolExecutor.java:1130)
at java.base/java.util.concurrent.ThreadPoolExecutor$Worker.run(ThreadPoolExecutor.java:630)
at java.base/java.lang.Thread.run(Thread.java:831)
]]>
            </full-stacktrace>
          </exception> <!-- java.lang.AssertionError -->
          <reporter-output>
          </reporter-output>
        </test-method> <!-- validateCreateCustomerAPIWithInValidSecretkey -->
        <test-method signature="validateCreateCustomerAPIWithInValidSecretkey(java.util.Hashtable)[pri:0, instance:com.home.APITestingFramework.testcases.CreateCustomerTest@3d3f761a]" started-at="2023-02-24T11:17:10 IST" name="validateCreateCustomerAPIWithInValidSecretkey" data-provider="data" finished-at="2023-02-24T11:17:14 IST" duration-ms="3245" status="FAIL">
          <params>
            <param index="0">
              <value>
                <![CDATA[{email=anilcusttwo@gmail.com, name=Anil Patil, description=This is a test customer two for API Testing Framework}]]>
              </value>
            </param>
          </params>
          <exception class="java.lang.AssertionError">
            <message>
              <![CDATA[expected [200] but found [401]]]>
            </message>
            <full-stacktrace>
              <![CDATA[java.lang.AssertionError: expected [200] but found [401]
at org.testng.Assert.fail(Assert.java:110)
at org.testng.Assert.failNotEquals(Assert.java:1413)
at org.testng.Assert.assertEqualsImpl(Assert.java:149)
at org.testng.Assert.assertEquals(Assert.java:131)
at org.testng.Assert.assertEquals(Assert.java:1240)
at org.testng.Assert.assertEquals(Assert.java:1274)
at com.home.APITestingFramework.testcases.CreateCustomerTest.validateCreateCustomerAPIWithInValidSecretkey(CreateCustomerTest.java:44)
at java.base/jdk.internal.reflect.NativeMethodAccessorImpl.invoke0(Native Method)
at java.base/jdk.internal.reflect.NativeMethodAccessorImpl.invoke(NativeMethodAccessorImpl.java:78)
at java.base/jdk.internal.reflect.DelegatingMethodAccessorImpl.invoke(DelegatingMethodAccessorImpl.java:43)
at java.base/java.lang.reflect.Method.invoke(Method.java:567)
at org.testng.internal.invokers.MethodInvocationHelper.invokeMethod(MethodInvocationHelper.java:139)
at org.testng.internal.invokers.TestInvoker.invokeMethod(TestInvoker.java:677)
at org.testng.internal.invokers.TestInvoker.invokeTestMethod(TestInvoker.java:221)
at org.testng.internal.invokers.TestMethodWithDataProviderMethodWorker.call(TestMethodWithDataProviderMethodWorker.java:80)
at org.testng.internal.invokers.TestMethodWithDataProviderMethodWorker.call(TestMethodWithDataProviderMethodWorker.java:17)
at java.base/java.util.concurrent.FutureTask.run(FutureTask.java:264)
at java.base/java.util.concurrent.Executors$RunnableAdapter.call(Executors.java:515)
at java.base/java.util.concurrent.FutureTask.run(FutureTask.java:264)
at java.base/java.util.concurrent.ThreadPoolExecutor.runWorker(ThreadPoolExecutor.java:1130)
at java.base/java.util.concurrent.ThreadPoolExecutor$Worker.run(ThreadPoolExecutor.java:630)
at java.base/java.lang.Thread.run(Thread.java:831)
]]>
            </full-stacktrace>
          </exception> <!-- java.lang.AssertionError -->
          <reporter-output>
          </reporter-output>
        </test-method> <!-- validateCreateCustomerAPIWithInValidSecretkey -->
        <test-method signature="validateCreateCustomerAPIWithValidSecretkey(java.util.Hashtable)[pri:0, instance:com.home.APITestingFramework.testcases.CreateCustomerTest@3d3f761a]" started-at="2023-02-24T11:17:14 IST" name="validateCreateCustomerAPIWithValidSecretkey" data-provider="data" finished-at="2023-02-24T11:17:14 IST" duration-ms="596" status="PASS">
          <params>
            <param index="0">
              <value>
                <![CDATA[{email=smitacustone@gmail.com, name=Smita Patil, description=This is a test customer one for API Testing Framework}]]>
              </value>
            </param>
          </params>
          <reporter-output>
          </reporter-output>
        </test-method> <!-- validateCreateCustomerAPIWithValidSecretkey -->
        <test-method signature="validateCreateCustomerAPIWithValidSecretkey(java.util.Hashtable)[pri:0, instance:com.home.APITestingFramework.testcases.CreateCustomerTest@3d3f761a]" started-at="2023-02-24T11:17:14 IST" name="validateCreateCustomerAPIWithValidSecretkey" data-provider="data" finished-at="2023-02-24T11:17:14 IST" duration-ms="595" status="PASS">
          <params>
            <param index="0">
              <value>
                <![CDATA[{email=anilcusttwo@gmail.com, name=Anil Patil, description=This is a test customer two for API Testing Framework}]]>
              </value>
            </param>
          </params>
          <reporter-output>
          </reporter-output>
        </test-method> <!-- validateCreateCustomerAPIWithValidSecretkey -->
        <test-method signature="validateCreateCustomerAPIWithValidSecretkey(java.util.Hashtable)[pri:0, instance:com.home.APITestingFramework.testcases.CreateCustomerTest@3d3f761a]" started-at="2023-02-24T11:17:14 IST" name="validateCreateCustomerAPIWithValidSecretkey" data-provider="data" finished-at="2023-02-24T11:17:15 IST" duration-ms="799" status="PASS">
          <params>
            <param index="0">
              <value>
                <![CDATA[{email=aradhya@gmail.com, name=Aradhya Patil, description=Third customer for API testing framework}]]>
              </value>
            </param>
          </params>
          <reporter-output>
          </reporter-output>
        </test-method> <!-- validateCreateCustomerAPIWithValidSecretkey -->
      </class> <!-- com.home.APITestingFramework.testcases.CreateCustomerTest -->
    </test> <!-- Create Customer API Test -->
    <test started-at="2023-02-24T11:17:15 IST" name="Delete Customer API Test" finished-at="2023-02-24T11:17:16 IST" duration-ms="577">
      <class name="com.home.APITestingFramework.testcases.DeleteCustomerTest">
        <test-method is-config="true" signature="setUp()[pri:0, instance:com.home.APITestingFramework.testcases.DeleteCustomerTest@74f7d1d2]" started-at="2023-02-24T11:17:10 IST" name="setUp" finished-at="2023-02-24T11:17:10 IST" duration-ms="726" status="PASS">
          <reporter-output>
          </reporter-output>
        </test-method> <!-- setUp -->
        <test-method signature="deleteCustomerWithValidCustomerId(java.util.Hashtable)[pri:0, instance:com.home.APITestingFramework.testcases.DeleteCustomerTest@74f7d1d2]" started-at="2023-02-24T11:17:15 IST" name="deleteCustomerWithValidCustomerId" data-provider="data" finished-at="2023-02-24T11:17:16 IST" duration-ms="555" status="FAIL">
          <params>
            <param index="0">
              <value>
                <![CDATA[{id=cus_NPiez6RuJoSF3f}]]>
              </value>
            </param>
          </params>
          <exception class="java.lang.AssertionError">
            <message>
              <![CDATA[id key is not present in response expected [true] but found [false]]]>
            </message>
            <full-stacktrace>
              <![CDATA[java.lang.AssertionError: id key is not present in response expected [true] but found [false]
at org.testng.Assert.fail(Assert.java:110)
at org.testng.Assert.failNotEquals(Assert.java:1413)
at org.testng.Assert.assertTrue(Assert.java:56)
at com.home.APITestingFramework.testcases.DeleteCustomerTest.deleteCustomerWithValidCustomerId(DeleteCustomerTest.java:44)
at java.base/jdk.internal.reflect.NativeMethodAccessorImpl.invoke0(Native Method)
at java.base/jdk.internal.reflect.NativeMethodAccessorImpl.invoke(NativeMethodAccessorImpl.java:78)
at java.base/jdk.internal.reflect.DelegatingMethodAccessorImpl.invoke(DelegatingMethodAccessorImpl.java:43)
at java.base/java.lang.reflect.Method.invoke(Method.java:567)
at org.testng.internal.invokers.MethodInvocationHelper.invokeMethod(MethodInvocationHelper.java:139)
at org.testng.internal.invokers.TestInvoker.invokeMethod(TestInvoker.java:677)
at org.testng.internal.invokers.TestInvoker.invokeTestMethod(TestInvoker.java:221)
at org.testng.internal.invokers.TestMethodWithDataProviderMethodWorker.call(TestMethodWithDataProviderMethodWorker.java:80)
at org.testng.internal.invokers.TestMethodWithDataProviderMethodWorker.call(TestMethodWithDataProviderMethodWorker.java:17)
at java.base/java.util.concurrent.FutureTask.run(FutureTask.java:264)
at java.base/java.util.concurrent.Executors$RunnableAdapter.call(Executors.java:515)
at java.base/java.util.concurrent.FutureTask.run(FutureTask.java:264)
at java.base/java.util.concurrent.ThreadPoolExecutor.runWorker(ThreadPoolExecutor.java:1130)
at java.base/java.util.concurrent.ThreadPoolExecutor$Worker.run(ThreadPoolExecutor.java:630)
at java.base/java.lang.Thread.run(Thread.java:831)
]]>
            </full-stacktrace>
          </exception> <!-- java.lang.AssertionError -->
          <reporter-output>
          </reporter-output>
        </test-method> <!-- deleteCustomerWithValidCustomerId -->
        <test-method signature="deleteCustomerWithValidCustomerId(java.util.Hashtable)[pri:0, instance:com.home.APITestingFramework.testcases.DeleteCustomerTest@74f7d1d2]" started-at="2023-02-24T11:17:15 IST" name="deleteCustomerWithValidCustomerId" data-provider="data" finished-at="2023-02-24T11:17:16 IST" duration-ms="443" status="FAIL">
          <params>
            <param index="0">
              <value>
                <![CDATA[{id=cus_NPieq7cBd7uLpA}]]>
              </value>
            </param>
          </params>
          <exception class="java.lang.AssertionError">
            <message>
              <![CDATA[id key is not present in response expected [true] but found [false]]]>
            </message>
            <full-stacktrace>
              <![CDATA[java.lang.AssertionError: id key is not present in response expected [true] but found [false]
at org.testng.Assert.fail(Assert.java:110)
at org.testng.Assert.failNotEquals(Assert.java:1413)
at org.testng.Assert.assertTrue(Assert.java:56)
at com.home.APITestingFramework.testcases.DeleteCustomerTest.deleteCustomerWithValidCustomerId(DeleteCustomerTest.java:44)
at java.base/jdk.internal.reflect.NativeMethodAccessorImpl.invoke0(Native Method)
at java.base/jdk.internal.reflect.NativeMethodAccessorImpl.invoke(NativeMethodAccessorImpl.java:78)
at java.base/jdk.internal.reflect.DelegatingMethodAccessorImpl.invoke(DelegatingMethodAccessorImpl.java:43)
at java.base/java.lang.reflect.Method.invoke(Method.java:567)
at org.testng.internal.invokers.MethodInvocationHelper.invokeMethod(MethodInvocationHelper.java:139)
at org.testng.internal.invokers.TestInvoker.invokeMethod(TestInvoker.java:677)
at org.testng.internal.invokers.TestInvoker.invokeTestMethod(TestInvoker.java:221)
at org.testng.internal.invokers.TestMethodWithDataProviderMethodWorker.call(TestMethodWithDataProviderMethodWorker.java:80)
at org.testng.internal.invokers.TestMethodWithDataProviderMethodWorker.call(TestMethodWithDataProviderMethodWorker.java:17)
at java.base/java.util.concurrent.FutureTask.run(FutureTask.java:264)
at java.base/java.util.concurrent.Executors$RunnableAdapter.call(Executors.java:515)
at java.base/java.util.concurrent.FutureTask.run(FutureTask.java:264)
at java.base/java.util.concurrent.ThreadPoolExecutor.runWorker(ThreadPoolExecutor.java:1130)
at java.base/java.util.concurrent.ThreadPoolExecutor$Worker.run(ThreadPoolExecutor.java:630)
at java.base/java.lang.Thread.run(Thread.java:831)
]]>
            </full-stacktrace>
          </exception> <!-- java.lang.AssertionError -->
          <reporter-output>
          </reporter-output>
        </test-method> <!-- deleteCustomerWithValidCustomerId -->
        <test-method is-config="true" signature="tearDown()[pri:0, instance:com.home.APITestingFramework.testcases.DeleteCustomerTest@74f7d1d2]" started-at="2023-02-24T11:17:16 IST" name="tearDown" finished-at="2023-02-24T11:17:16 IST" duration-ms="1" status="PASS">
          <reporter-output>
          </reporter-output>
        </test-method> <!-- tearDown -->
      </class> <!-- com.home.APITestingFramework.testcases.DeleteCustomerTest -->
    </test> <!-- Delete Customer API Test -->
  </suite> <!-- Suite -->
</testng-results>
